Workbook

Sheet idle_time_ratio_summary
A1: case_id | B1: human_idle_nores | C1: human_idle_nores_ratio | D1: human_idle_dynamic | E1: human_idle_dynamic_ratio | F1: human_idle_ratio_diff_nores_minus_dynamic | G1: human_nores_idle_ratio_higher | H1: robot_idle_nores | I1: robot_idle_nores_ratio | J1: robot_idle_dynamic | K1: robot_idle_dynamic_ratio | L1: robot_idle_ratio_diff_nores_minus_dynamic | M1: robot_nores_idle_ratio_higher | N1: robot_nores_idle_ratio_higher_5pct | O1: robot_nores_idle_ratio_higher_effect | P1: robot_dynamic_idle_ratio_higher_effect | Q1: human_nores_idle_ratio_higher_effect | R1: human_nores_idle_ratio_higher2 | S1: human_nores_idle_ratio_higher5pct
A2: 20260616_163957 | B2: 2.59 | C2: 0.03 | D2: 3.94 | E2: 0.05 | F2: -0.02 | G2: 0 | H2: 29.38 | I2: 0.37 | J2: 22.64 | K2: 0.31 | L2: 0.06 | M2: 1 | N2: =IF(L2>=0.05,1,0) -> 1 | O2: =IF(idle_time_ratio_summary[[#This Row],[robot_nores_idle_ratio_higher]]=1,idle_time_ratio_summary[[#This Row],[robot_idle_ratio_diff_nores_minus_dynamic]],0) -> 0.06 | P2: =IF(idle_time_ratio_summary[[#This Row],[robot_nores_idle_ratio_higher]]=0,ABS(idle_time_ratio_summary[[#This Row],[robot_idle_ratio_diff_nores_minus_dynamic]]),0) -> 0 | Q2: =IF(idle_time_ratio_summary[[#This Row],[human_idle_ratio_diff_nores_minus_dynamic]]>0,idle_time_ratio_summary[[#This Row],[human_idle_ratio_diff_nores_minus_dynamic]],0) -> 0 | R2: =IF(idle_time_ratio_summary[[#This Row],[human_idle_ratio_diff_nores_minus_dynamic]]<0,-idle_time_ratio_summary[[#This Row],[human_idle_ratio_diff_nores_minus_dynamic]],0) -> 0.02 | S2: =IF(idle_time_ratio_summary[[#This Row],[human_nores_idle_ratio_higher2]]>=0.05,1,0) -> 0
A3: 20260616_165213 | B3: 3.21 | C3: 0.04 | D3: 5.26 | E3: 0.07 | F3: -0.03 | G3: 0 | H3: 29.16 | I3: 0.36 | J3: 23.09 | K3: 0.31 | L3: 0.05 | M3: 1 | N3: =IF(L3>=0.05,1,0) -> 1 | O3: =IF(idle_time_ratio_summary[[#This Row],[robot_nores_idle_ratio_higher]]=1,idle_time_ratio_summary[[#This Row],[robot_idle_ratio_diff_nores_minus_dynamic]],0) -> 0.05 | P3: =IF(idle_time_ratio_summary[[#This Row],[robot_nores_idle_ratio_higher]]=0,ABS(idle_time_ratio_summary[[#This Row],[robot_idle_ratio_diff_nores_minus_dynamic]]),0) -> 0 | Q3: =IF(idle_time_ratio_summary[[#This Row],[human_idle_ratio_diff_nores_minus_dynamic]]>0,idle_time_ratio_summary[[#This Row],[human_idle_ratio_diff_nores_minus_dynamic]],0) -> 0 | R3: =IF(idle_time_ratio_summary[[#This Row],[human_idle_ratio_diff_nores_minus_dynamic]]<0,-idle_time_ratio_summary[[#This Row],[human_idle_ratio_diff_nores_minus_dynamic]],0) -> 0.03 | S3: =IF(idle_time_ratio_summary[[#This Row],[human_nores_idle_ratio_higher2]]>=0.05,1,0) -> 0
A4: 20260617_161127 | B4: 2.9 | C4: 0.03 | D4: 3.37 | E4: 0.04 | F4: -0.01 | G4: 0 | H4: 46.26 | I4: 0.48 | J4: 41.13 | K4: 0.45 | L4: 0.03 | M4: 1 | N4: =IF(L4>=0.05,1,0) -> 0 | O4: =IF(idle_time_ratio_summary[[#This Row],[robot_nores_idle_ratio_higher]]=1,idle_time_ratio_summary[[#This Row],[robot_idle_ratio_diff_nores_minus_dynamic]],0) -> 0.03 | P4: =IF(idle_time_ratio_summary[[#This Row],[robot_nores_idle_ratio_higher]]=0,ABS(idle_time_ratio_summary[[#This Row],[robot_idle_ratio_diff_nores_minus_dynamic]]),0) -> 0 | Q4: =IF(idle_time_ratio_summary[[#This Row],[human_idle_ratio_diff_nores_minus_dynamic]]>0,idle_time_ratio_summary[[#This Row],[human_idle_ratio_diff_nores_minus_dynamic]],0) -> 0 | R4: =IF(idle_time_ratio_summary[[#This Row],[human_idle_ratio_diff_nores_minus_dynamic]]<0,-idle_time_ratio_summary[[#This Row],[human_idle_ratio_diff_nores_minus_dynamic]],0) -> 0.01 | S4: =IF(idle_time_ratio_summary[[#This Row],[human_nores_idle_ratio_higher2]]>=0.05,1,0) -> 0
A5: 20260617_161833 | B5: 3.79 | C5: 0.05 | D5: 11.8 | E5: 0.16 | F5: -0.11 | G5: 0 | H5: 24.49 | I5: 0.32 | J5: 14.94 | K5: 0.2 | L5: 0.12 | M5: 1 | N5: =IF(L5>=0.05,1,0) -> 1 | O5: =IF(idle_time_ratio_summary[[#This Row],[robot_nores_idle_ratio_higher]]=1,idle_time_ratio_summary[[#This Row],[robot_idle_ratio_diff_nores_minus_dynamic]],0) -> 0.12 | P5: =IF(idle_time_ratio_summary[[#This Row],[robot_nores_idle_ratio_higher]]=0,ABS(idle_time_ratio_summary[[#This Row],[robot_idle_ratio_diff_nores_minus_dynamic]]),0) -> 0 | Q5: =IF(idle_time_ratio_summary[[#This Row],[human_idle_ratio_diff_nores_minus_dynamic]]>0,idle_time_ratio_summary[[#This Row],[human_idle_ratio_diff_nores_minus_dynamic]],0) -> 0 | R5: =IF(idle_time_ratio_summary[[#This Row],[human_idle_ratio_diff_nores_minus_dynamic]]<0,-idle_time_ratio_summary[[#This Row],[human_idle_ratio_diff_nores_minus_dynamic]],0) -> 0.11 | S5: =IF(idle_time_ratio_summary[[#This Row],[human_nores_idle_ratio_higher2]]>=0.05,1,0) -> 1
A6: 20260617_162610 | B6: 2.12 | C6: 0.02 | D6: 2.61 | E6: 0.03 | F6: -0.01 | G6: 0 | H6: 44.41 | I6: 0.46 | J6: 24.7 | K6: 0.29 | L6: 0.17 | M6: 1 | N6: =IF(L6>=0.05,1,0) -> 1 | O6: =IF(idle_time_ratio_summary[[#This Row],[robot_nores_idle_ratio_higher]]=1,idle_time_ratio_summary[[#This Row],[robot_idle_ratio_diff_nores_minus_dynamic]],0) -> 0.17 | P6: =IF(idle_time_ratio_summary[[#This Row],[robot_nores_idle_ratio_higher]]=0,ABS(idle_time_ratio_summary[[#This Row],[robot_idle_ratio_diff_nores_minus_dynamic]]),0) -> 0 | Q6: =IF(idle_time_ratio_summary[[#This Row],[human_idle_ratio_diff_nores_minus_dynamic]]>0,idle_time_ratio_summary[[#This Row],[human_idle_ratio_diff_nores_minus_dynamic]],0) -> 0 | R6: =IF(idle_time_ratio_summary[[#This Row],[human_idle_ratio_diff_nores_minus_dynamic]]<0,-idle_time_ratio_summary[[#This Row],[human_idle_ratio_diff_nores_minus_dynamic]],0) -> 0.01 | S6: =IF(idle_time_ratio_summary[[#This Row],[human_nores_idle_ratio_higher2]]>=0.05,1,0) -> 0
A7: 20260617_163225 | B7: 0.73 | C7: 0.01 | D7: 9.46 | E7: 0.11 | F7: -0.1 | G7: 0 | H7: 33.21 | I7: 0.39 | J7: 24.08 | K7: 0.29 | L7: 0.1 | M7: 1 | N7: =IF(L7>=0.05,1,0) -> 1 | O7: =IF(idle_time_ratio_summary[[#This Row],[robot_nores_idle_ratio_higher]]=1,idle_time_ratio_summary[[#This Row],[robot_idle_ratio_diff_nores_minus_dynamic]],0) -> 0.1 | P7: =IF(idle_time_ratio_summary[[#This Row],[robot_nores_idle_ratio_higher]]=0,ABS(idle_time_ratio_summary[[#This Row],[robot_idle_ratio_diff_nores_minus_dynamic]]),0) -> 0 | Q7: =IF(idle_time_ratio_summary[[#This Row],[human_idle_ratio_diff_nores_minus_dynamic]]>0,idle_time_ratio_summary[[#This Row],[human_idle_ratio_diff_nores_minus_dynamic]],0) -> 0 | R7: =IF(idle_time_ratio_summary[[#This Row],[human_idle_ratio_diff_nores_minus_dynamic]]<0,-idle_time_ratio_summary[[#This Row],[human_idle_ratio_diff_nores_minus_dynamic]],0) -> 0.1 | S7: =IF(idle_time_ratio_summary[[#This Row],[human_nores_idle_ratio_higher2]]>=0.05,1,0) -> 1
A8: 20260617_163852 | B8: 3.39 | C8: 0.04 | D8: 17.2 | E8: 0.2 | F8: -0.16 | G8: 0 | H8: 28.19 | I8: 0.36 | J8: 16.79 | K8: 0.2 | L8: 0.16 | M8: 1 | N8: =IF(L8>=0.05,1,0) -> 1 | O8: =IF(idle_time_ratio_summary[[#This Row],[robot_nores_idle_ratio_higher]]=1,idle_time_ratio_summary[[#This Row],[robot_idle_ratio_diff_nores_minus_dynamic]],0) -> 0.16 | P8: =IF(idle_time_ratio_summary[[#This Row],[robot_nores_idle_ratio_higher]]=0,ABS(idle_time_ratio_summary[[#This Row],[robot_idle_ratio_diff_nores_minus_dynamic]]),0) -> 0 | Q8: =IF(idle_time_ratio_summary[[#This Row],[human_idle_ratio_diff_nores_minus_dynamic]]>0,idle_time_ratio_summary[[#This Row],[human_idle_ratio_diff_nores_minus_dynamic]],0) -> 0 | R8: =IF(idle_time_ratio_summary[[#This Row],[human_idle_ratio_diff_nores_minus_dynamic]]<0,-idle_time_ratio_summary[[#This Row],[human_idle_ratio_diff_nores_minus_dynamic]],0) -> 0.16 | S8: =IF(idle_time_ratio_summary[[#This Row],[human_nores_idle_ratio_higher2]]>=0.05,1,0) -> 1
A9: 20260617_164554 | B9: 7.19 | C9: 0.1 | D9: 6.16 | E9: 0.09 | F9: 0.01 | G9: 1 | H9: 18.77 | I9: 0.27 | J9: 17.72 | K9: 0.26 | L9: 0.01 | M9: 1 | N9: =IF(L9>=0.05,1,0) -> 0 | O9: =IF(idle_time_ratio_summary[[#This Row],[robot_nores_idle_ratio_higher]]=1,idle_time_ratio_summary[[#This Row],[robot_idle_ratio_diff_nores_minus_dynamic]],0) -> 0.01 | P9: =IF(idle_time_ratio_summary[[#This Row],[robot_nores_idle_ratio_higher]]=0,ABS(idle_time_ratio_summary[[#This Row],[robot_idle_ratio_diff_nores_minus_dynamic]]),0) -> 0 | Q9: =IF(idle_time_ratio_summary[[#This Row],[human_idle_ratio_diff_nores_minus_dynamic]]>0,idle_time_ratio_summary[[#This Row],[human_idle_ratio_diff_nores_minus_dynamic]],0) -> 0.01 | R9: =IF(idle_time_ratio_summary[[#This Row],[human_idle_ratio_diff_nores_minus_dynamic]]<0,-idle_time_ratio_summary[[#This Row],[human_idle_ratio_diff_nores_minus_dynamic]],0) -> 0 | S9: =IF(idle_time_ratio_summary[[#This Row],[human_nores_idle_ratio_higher2]]>=0.05,1,0) -> 0
A10: 20260617_165310 | B10: 6.09 | C10: 0.09 | D10: 4.22 | E10: 0.06 | F10: 0.03 | G10: 1 | H10: 16.88 | I10: 0.25 | J10: 14.98 | K10: 0.23 | L10: 0.02 | M10: 1 | N10: =IF(L10>=0.05,1,0) -> 0 | O10: =IF(idle_time_ratio_summary[[#This Row],[robot_nores_idle_ratio_higher]]=1,idle_time_ratio_summary[[#This Row],[robot_idle_ratio_diff_nores_minus_dynamic]],0) -> 0.02 | P10: =IF(idle_time_ratio_summary[[#This Row],[robot_nores_idle_ratio_higher]]=0,ABS(idle_time_ratio_summary[[#This Row],[robot_idle_ratio_diff_nores_minus_dynamic]]),0) -> 0 | Q10: =IF(idle_time_ratio_summary[[#This Row],[human_idle_ratio_diff_nores_minus_dynamic]]>0,idle_time_ratio_summary[[#This Row],[human_idle_ratio_diff_nores_minus_dynamic]],0) -> 0.03 | R10: =IF(idle_time_ratio_summary[[#This Row],[human_idle_ratio_diff_nores_minus_dynamic]]<0,-idle_time_ratio_summary[[#This Row],[human_idle_ratio_diff_nores_minus_dynamic]],0) -> 0 | S10: =IF(idle_time_ratio_summary[[#This Row],[human_nores_idle_ratio_higher2]]>=0.05,1,0) -> 0
A11: 20260617_170056 | B11: 8.47 | C11: 0.12 | D11: 7.25 | E11: 0.11 | F11: 0.01 | G11: 1 | H11: 16.79 | I11: 0.25 | J11: 15.52 | K11: 0.23 | L11: 0.02 | M11: 1 | N11: =IF(L11>=0.05,1,0) -> 0 | O11: =IF(idle_time_ratio_summary[[#This Row],[robot_nores_idle_ratio_higher]]=1,idle_time_ratio_summary[[#This Row],[robot_idle_ratio_diff_nores_minus_dynamic]],0) -> 0.02 | P11: =IF(idle_time_ratio_summary[[#This Row],[robot_nores_idle_ratio_higher]]=0,ABS(idle_time_ratio_summary[[#This Row],[robot_idle_ratio_diff_nores_minus_dynamic]]),0) -> 0 | Q11: =IF(idle_time_ratio_summary[[#This Row],[human_idle_ratio_diff_nores_minus_dynamic]]>0,idle_time_ratio_summary[[#This Row],[human_idle_ratio_diff_nores_minus_dynamic]],0) -> 0.01 | R11: =IF(idle_time_ratio_summary[[#This Row],[human_idle_ratio_diff_nores_minus_dynamic]]<0,-idle_time_ratio_summary[[#This Row],[human_idle_ratio_diff_nores_minus_dynamic]],0) -> 0 | S11: =IF(idle_time_ratio_summary[[#This Row],[human_nores_idle_ratio_higher2]]>=0.05,1,0) -> 0
A12: 20260617_170735 | B12: 4.85 | C12: 0.07 | D12: 6.35 | E12: 0.09 | F12: -0.02 | G12: 0 | H12: 20.18 | I12: 0.28 | J12: 18.57 | K12: 0.27 | L12: 0.01 | M12: 1 | N12: =IF(L12>=0.05,1,0) -> 0 | O12: =IF(idle_time_ratio_summary[[#This Row],[robot_nores_idle_ratio_higher]]=1,idle_time_ratio_summary[[#This Row],[robot_idle_ratio_diff_nores_minus_dynamic]],0) -> 0.01 | P12: =IF(idle_time_ratio_summary[[#This Row],[robot_nores_idle_ratio_higher]]=0,ABS(idle_time_ratio_summary[[#This Row],[robot_idle_ratio_diff_nores_minus_dynamic]]),0) -> 0 | Q12: =IF(idle_time_ratio_summary[[#This Row],[human_idle_ratio_diff_nores_minus_dynamic]]>0,idle_time_ratio_summary[[#This Row],[human_idle_ratio_diff_nores_minus_dynamic]],0) -> 0 | R12: =IF(idle_time_ratio_summary[[#This Row],[human_idle_ratio_diff_nores_minus_dynamic]]<0,-idle_time_ratio_summary[[#This Row],[human_idle_ratio_diff_nores_minus_dynamic]],0) -> 0.02 | S12: =IF(idle_time_ratio_summary[[#This Row],[human_nores_idle_ratio_higher2]]>=0.05,1,0) -> 0
A13: 20260617_214847 | B13: 0 | C13: 0 | D13: 0.53 | E13: 0.01 | F13: -0.01 | G13: 0 | H13: 51.62 | I13: 0.5 | J13: 41.33 | K13: 0.45 | L13: 0.05 | M13: 1 | N13: =IF(L13>=0.05,1,0) -> 1 | O13: =IF(idle_time_ratio_summary[[#This Row],[robot_nores_idle_ratio_higher]]=1,idle_time_ratio_summary[[#This Row],[robot_idle_ratio_diff_nores_minus_dynamic]],0) -> 0.05 | P13: =IF(idle_time_ratio_summary[[#This Row],[robot_nores_idle_ratio_higher]]=0,ABS(idle_time_ratio_summary[[#This Row],[robot_idle_ratio_diff_nores_minus_dynamic]]),0) -> 0 | Q13: =IF(idle_time_ratio_summary[[#This Row],[human_idle_ratio_diff_nores_minus_dynamic]]>0,idle_time_ratio_summary[[#This Row],[human_idle_ratio_diff_nores_minus_dynamic]],0) -> 0 | R13: =IF(idle_time_ratio_summary[[#This Row],[human_idle_ratio_diff_nores_minus_dynamic]]<0,-idle_time_ratio_summary[[#This Row],[human_idle_ratio_diff_nores_minus_dynamic]],0) -> 0.01 | S13: =IF(idle_time_ratio_summary[[#This Row],[human_nores_idle_ratio_higher2]]>=0.05,1,0) -> 0
... A77: 20260621_223602 | B77: 2.92 | C77: 0.04 | D77: 9.48 | E77: 0.12 | F77: -0.08 | G77: 0 | H77: 25.3 | I77: 0.33 | J77: 19.61 | K77: 0.25 | L77: 0.08 | M77: 1 | N77: =IF(L77>=0.05,1,0) -> 1 | O77: =IF(idle_time_ratio_summary[[#This Row],[robot_nores_idle_ratio_higher]]=1,idle_time_ratio_summary[[#This Row],[robot_idle_ratio_diff_nores_minus_dynamic]],0) -> 0.08 | P77: =IF(idle_time_ratio_summary[[#This Row],[robot_nores_idle_ratio_higher]]=0,ABS(idle_time_ratio_summary[[#This Row],[robot_idle_ratio_diff_nores_minus_dynamic]]),0) -> 0 | Q77: =IF(idle_time_ratio_summary[[#This Row],[human_idle_ratio_diff_nores_minus_dynamic]]>0,idle_time_ratio_summary[[#This Row],[human_idle_ratio_diff_nores_minus_dynamic]],0) -> 0 | R77: =IF(idle_time_ratio_summary[[#This Row],[human_idle_ratio_diff_nores_minus_dynamic]]<0,-idle_time_ratio_summary[[#This Row],[human_idle_ratio_diff_nores_minus_dynamic]],0) -> 0.08 | S77: =IF(idle_time_ratio_summary[[#This Row],[human_nores_idle_ratio_higher2]]>=0.05,1,0) -> 1
G78: =SUM(G2:G77) -> 11 | M78: =SUM(M2:M77) -> 54 | N78: =SUM(N2:N77) -> 38 | O78: =IF(idle_time_ratio_summary[[#This Row],[robot_nores_idle_ratio_higher]]=1,idle_time_ratio_summary[[#This Row],[robot_idle_ratio_diff_nores_minus_dynamic]],0) -> 0 | P78: =IF(idle_time_ratio_summary[[#This Row],[robot_nores_idle_ratio_higher]]=0,ABS(idle_time_ratio_summary[[#This Row],[robot_idle_ratio_diff_nores_minus_dynamic]]),0) -> 0 | Q78: =IF(idle_time_ratio_summary[[#This Row],[human_idle_ratio_diff_nores_minus_dynamic]]>0,idle_time_ratio_summary[[#This Row],[human_idle_ratio_diff_nores_minus_dynamic]],0) -> 0 | R78: =IF(idle_time_ratio_summary[[#This Row],[human_idle_ratio_diff_nores_minus_dynamic]]<0,-idle_time_ratio_summary[[#This Row],[human_idle_ratio_diff_nores_minus_dynamic]],0) -> 0 | S78: =IF(idle_time_ratio_summary[[#This Row],[human_nores_idle_ratio_higher2]]>=0.05,1,0) -> 0
O79: =SUBTOTAL(109,idle_time_ratio_summary[robot_nores_idle_ratio_higher_effect])/71 -> 0.065633803 | P79: =SUBTOTAL(109,idle_time_ratio_summary[robot_dynamic_idle_ratio_higher_effect])/71 -> 0.0028169014 | Q79: =SUBTOTAL(109,idle_time_ratio_summary[human_nores_idle_ratio_higher_effect])/71 -> 0.004084507 | R79: =SUBTOTAL(109,idle_time_ratio_summary[human_nores_idle_ratio_higher2])/71 -> 0.032535211 | S79: =SUBTOTAL(109,idle_time_ratio_summary[human_nores_idle_ratio_higher5pct]) -> 19

Sheet batch_final_timeline_by_case
A1: case_id | B1: num_events | C1: offline_makespan | D1: final_nores_makespan | E1: final_dynamic_makespan | F1: final_nores_minus_dynamic | G1: dynamic_final_better | H1: nores_final_better | I1: tie | J1: comparison_rule | K1: tie_tolerance_seconds | L1: final_comparison_png | M1: output_dir | N1: human_nores_idle_ratio_higher | O1: robot_nores_idle_ratio_higher
A2: 20260618_145723 | B2: 0 | C2: 72.63 | D2: 67.78 | E2: 67.79 | F2: -0.01 | G2: 0 | H2: 0 | I2: 1 | J2: no_failure_tolerance | K2: 0.1 | L2: C:\Users\c2466\Desktop\task_monitor\batch_real_nores_outputs\20260618_145723\comparison_gantt.png | M2: C:\Users\c2466\Desktop\task_monitor\batch_real_nores_outputs\20260618_145723 | N2: =_xlfn.XLOOKUP(A2,idle_time_ratio_summary!A:A,idle_time_ratio_summary!G:G,"") -> 0 | O2: =_xlfn.XLOOKUP(A2,idle_time_ratio_summary!A:A,idle_time_ratio_summary!M:M,"") -> 0
A3: 20260618_151245 | B3: 0 | C3: 72.63 | D3: 67.89 | E3: 67.91 | F3: -0.02 | G3: 0 | H3: 0 | I3: 1 | J3: no_failure_tolerance | K3: 0.1 | L3: C:\Users\c2466\Desktop\task_monitor\batch_real_nores_outputs\20260618_151245\comparison_gantt.png | M3: C:\Users\c2466\Desktop\task_monitor\batch_real_nores_outputs\20260618_151245 | N3: =_xlfn.XLOOKUP(A3,idle_time_ratio_summary!A:A,idle_time_ratio_summary!G:G,"") -> 0 | O3: =_xlfn.XLOOKUP(A3,idle_time_ratio_summary!A:A,idle_time_ratio_summary!M:M,"") -> 0
A4: 20260621_172052 | B4: 0 | C4: 72.63 | D4: 67.72 | E4: 67.72 | F4: 0 | G4: 0 | H4: 0 | I4: 1 | J4: no_failure_tolerance | K4: 0.1 | L4: C:\Users\c2466\Desktop\task_monitor\batch_real_nores_outputs\20260621_172052\comparison_gantt.png | M4: C:\Users\c2466\Desktop\task_monitor\batch_real_nores_outputs\20260621_172052 | N4: =_xlfn.XLOOKUP(A4,idle_time_ratio_summary!A:A,idle_time_ratio_summary!G:G,"") -> 0 | O4: =_xlfn.XLOOKUP(A4,idle_time_ratio_summary!A:A,idle_time_ratio_summary!M:M,"") -> 0
A5: 20260621_175246 | B5: 0 | C5: 72.63 | D5: 67.92 | E5: 67.96 | F5: -0.04 | G5: 0 | H5: 0 | I5: 1 | J5: no_failure_tolerance | K5: 0.1 | L5: C:\Users\c2466\Desktop\task_monitor\batch_real_nores_outputs\20260621_175246\comparison_gantt.png | M5: C:\Users\c2466\Desktop\task_monitor\batch_real_nores_outputs\20260621_175246 | N5: =_xlfn.XLOOKUP(A5,idle_time_ratio_summary!A:A,idle_time_ratio_summary!G:G,"") -> 0 | O5: =_xlfn.XLOOKUP(A5,idle_time_ratio_summary!A:A,idle_time_ratio_summary!M:M,"") -> 0
A6: 20260621_193120 | B6: 0 | C6: 72.63 | D6: 68.39 | E6: 68.42 | F6: -0.03 | G6: 0 | H6: 0 | I6: 1 | J6: no_failure_tolerance | K6: 0.1 | L6: C:\Users\c2466\Desktop\task_monitor\batch_real_nores_outputs\20260621_193120\comparison_gantt.png | M6: C:\Users\c2466\Desktop\task_monitor\batch_real_nores_outputs\20260621_193120 | N6: =_xlfn.XLOOKUP(A6,idle_time_ratio_summary!A:A,idle_time_ratio_summary!G:G,"") -> 0 | O6: =_xlfn.XLOOKUP(A6,idle_time_ratio_summary!A:A,idle_time_ratio_summary!M:M,"") -> 0
A7: 20260621_170757 | B7: 1 | C7: 72.63 | D7: 67.85 | E7: 65.35 | F7: 2.5 | G7: 1 | H7: 0 | I7: 0 | J7: failure_case_exact_difference | K7: 0 | L7: C:\Users\c2466\Desktop\task_monitor\batch_real_nores_outputs\20260621_170757\comparison_gantt.png | M7: C:\Users\c2466\Desktop\task_monitor\batch_real_nores_outputs\20260621_170757 | N7: =_xlfn.XLOOKUP(A7,idle_time_ratio_summary!A:A,idle_time_ratio_summary!G:G,"") -> 1 | O7: =_xlfn.XLOOKUP(A7,idle_time_ratio_summary!A:A,idle_time_ratio_summary!M:M,"") -> 1
A8: 20260621_171234 | B8: 1 | C8: 72.63 | D8: 67.93 | E8: 65.52 | F8: 2.41 | G8: 1 | H8: 0 | I8: 0 | J8: failure_case_exact_difference | K8: 0 | L8: C:\Users\c2466\Desktop\task_monitor\batch_real_nores_outputs\20260621_171234\comparison_gantt.png | M8: C:\Users\c2466\Desktop\task_monitor\batch_real_nores_outputs\20260621_171234 | N8: =_xlfn.XLOOKUP(A8,idle_time_ratio_summary!A:A,idle_time_ratio_summary!G:G,"") -> 1 | O8: =_xlfn.XLOOKUP(A8,idle_time_ratio_summary!A:A,idle_time_ratio_summary!M:M,"") -> 1
A9: 20260621_171649 | B9: 1 | C9: 72.63 | D9: 67.84 | E9: 65.87 | F9: 1.97 | G9: 1 | H9: 0 | I9: 0 | J9: failure_case_exact_difference | K9: 0 | L9: C:\Users\c2466\Desktop\task_monitor\batch_real_nores_outputs\20260621_171649\comparison_gantt.png | M9: C:\Users\c2466\Desktop\task_monitor\batch_real_nores_outputs\20260621_171649 | N9: =_xlfn.XLOOKUP(A9,idle_time_ratio_summary!A:A,idle_time_ratio_summary!G:G,"") -> 1 | O9: =_xlfn.XLOOKUP(A9,idle_time_ratio_summary!A:A,idle_time_ratio_summary!M:M,"") -> 1
A10: 20260621_172604 | B10: 1 | C10: 72.63 | D10: 67.71 | E10: 63.7 | F10: 4.01 | G10: 1 | H10: 0 | I10: 0 | J10: failure_case_exact_difference | K10: 0 | L10: C:\Users\c2466\Desktop\task_monitor\batch_real_nores_outputs\20260621_172604\comparison_gantt.png | M10: C:\Users\c2466\Desktop\task_monitor\batch_real_nores_outputs\20260621_172604 | N10: =_xlfn.XLOOKUP(A10,idle_time_ratio_summary!A:A,idle_time_ratio_summary!G:G,"") -> 1 | O10: =_xlfn.XLOOKUP(A10,idle_time_ratio_summary!A:A,idle_time_ratio_summary!M:M,"") -> 1
A11: 20260621_185411 | B11: 1 | C11: 72.63 | D11: 68.34 | E11: 67.65 | F11: 0.69 | G11: 1 | H11: 0 | I11: 0 | J11: failure_case_exact_difference | K11: 0 | L11: C:\Users\c2466\Desktop\task_monitor\batch_real_nores_outputs\20260621_185411\comparison_gantt.png | M11: C:\Users\c2466\Desktop\task_monitor\batch_real_nores_outputs\20260621_185411 | N11: =_xlfn.XLOOKUP(A11,idle_time_ratio_summary!A:A,idle_time_ratio_summary!G:G,"") -> 0 | O11: =_xlfn.XLOOKUP(A11,idle_time_ratio_summary!A:A,idle_time_ratio_summary!M:M,"") -> 1
A12: 20260621_212643 | B12: 1 | C12: 72.63 | D12: 67.85 | E12: 66.56 | F12: 1.29 | G12: 1 | H12: 0 | I12: 0 | J12: failure_case_exact_difference | K12: 0 | L12: C:\Users\c2466\Desktop\task_monitor\batch_real_nores_outputs\20260621_212643\comparison_gantt.png | M12: C:\Users\c2466\Desktop\task_monitor\batch_real_nores_outputs\20260621_212643 | N12: =_xlfn.XLOOKUP(A12,idle_time_ratio_summary!A:A,idle_time_ratio_summary!G:G,"") -> 1 | O12: =_xlfn.XLOOKUP(A12,idle_time_ratio_summary!A:A,idle_time_ratio_summary!M:M,"") -> 1
A13: 20260621_222707 | B13: 1 | C13: 72.63 | D13: 68.34 | E13: 68.64 | F13: -0.3 | G13: 0 | H13: 1 | I13: 0 | J13: failure_case_exact_difference | K13: 0 | L13: C:\Users\c2466\Desktop\task_monitor\batch_real_nores_outputs\20260621_222707\comparison_gantt.png | M13: C:\Users\c2466\Desktop\task_monitor\batch_real_nores_outputs\20260621_222707 | N13: =_xlfn.XLOOKUP(A13,idle_time_ratio_summary!A:A,idle_time_ratio_summary!G:G,"") -> 0 | O13: =_xlfn.XLOOKUP(A13,idle_time_ratio_summary!A:A,idle_time_ratio_summary!M:M,"") -> 0
... A77: 20260617_220342 | B77: 27 | C77: 72.63 | D77: 169.9192 | E77: 166.98 | F77: 2.9392 | G77: 1 | H77: 0 | I77: 0 | J77: failure_case_exact_difference | K77: 0 | L77: C:\Users\c2466\Desktop\task_monitor\batch_real_nores_outputs\20260617_220342\comparison_gantt.png | M77: C:\Users\c2466\Desktop\task_monitor\batch_real_nores_outputs\20260617_220342 | N77: =_xlfn.XLOOKUP(A77,idle_time_ratio_summary!A:A,idle_time_ratio_summary!G:G,"") -> 0 | O77: =_xlfn.XLOOKUP(A77,idle_time_ratio_summary!A:A,idle_time_ratio_summary!M:M,"") -> 1

Sheet batch_event_summary
A1: case_id | B1: step_idx | C1: failure_type | D1: decision_time | E1: csv_delay_time | F1: actual_incremental_delay | G1: applied_nores_delay | H1: delay_source | I1: nores_makespan | J1: dynamic_makespan_after_event | K1: nores_minus_dynamic | L1: target_task | M1: t1 | N1: t2 | O1: earlier_task | P1: later_task | Q1: order_base_duration | R1: order_required_task_actual_duration | S1: order_wrong_first_task_actual_duration | T1: order_later_standard_duration | U1: order_compensation_upper | V1: released_previous_delay | W1: observed_order_extra_delay
A2: 20260616_163957 | B2: 1 | C2: delay | D2: 14.858661 | E2: 2.9619 | F2: 2.97 | G2: 0 | H2: real_gantt_duration_synchronized | I2: 76.64 | J2: 76.77 | K2: -0.13 | L2: 5
A3: 20260616_163957 | B3: 2 | C3: delay | D3: 28.050393 | E3: 2.9619 | F3: 2.97 | G3: 0 | H3: real_gantt_duration_synchronized | I3: 76.8 | J3: 77.03 | K3: -0.23 | L3: 9
A4: 20260616_163957 | B4: 3 | C4: order | D4: 32.836813 | E4: 0 | F4: 0 | G4: 3.35 | H4: order_wrong_first_actual_plus_fixed_3.35_on_earlier_task | I4: 78.19 | J4: 75.39 | K4: 2.8 | L4: 10 | M4: 10 | N4: 12 | O4: 10 | P4: 12 | Q4: 3.28 | R4: 3.59 | S4: 3.28 | T4: 3.4638 | U4: 3.35 | V4: 0.18 | W4: 0
A5: 20260616_163957 | B5: 4 | C5: delay | D5: 36.474332 | E5: 1.797 | F5: 1.8 | G5: 0 | H5: real_gantt_duration_synchronized | I5: 76.95 | J5: 77.19 | K5: -0.24 | L5: 10
A6: 20260616_163957 | B6: 5 | C6: delay | D6: 55.80129 | E6: 1.7319 | F6: 1.74 | G6: 0 | H6: real_gantt_duration_synchronized | I6: 74.62 | J6: 74.26 | K6: 0.36 | L6: 18
A7: 20260616_163957 | B7: 6 | C7: order | D7: 56.863608 | E7: 0 | F7: 0.94 | G7: 3.35 | H7: order_wrong_first_actual_plus_fixed_3.35_on_earlier_task | I7: 77.304 | J7: 73.46 | K7: 3.844 | L7: 18 | M7: 18 | N7: 19 | O7: 18 | P7: 19 | Q7: 4.53 | R7: 3.46 | S7: 4.53 | T7: 3.594 | U7: 3.35 | V7: 1.74 | W7: 0.94
A8: 20260616_163957 | B8: 7 | C8: order | D8: 67.570381 | E8: 0 | F8: 0 | G8: 3.35 | H8: order_wrong_first_actual_plus_fixed_3.35_on_earlier_task | I8: 77.834 | J8: 71.19 | K8: 6.644 | L8: 22 | M8: 22 | N8: 23 | O8: 22 | P8: 23 | Q8: 3.05 | R8: 3.62 | S8: 3.05 | T8: 3.594 | U8: 3.35 | V8: 0.54 | W8: 0
A9: 20260616_163957 | B9: 8 | C9: delay | D9: 71.203735 | E9: 1.8096 | F9: 1.81 | G9: 0 | H9: real_gantt_duration_synchronized | I9: 76.864 | J9: 73 | K9: 3.864 | L9: 22
A10: 20260616_163957 | B10: 9 | C10: delay | D10: 73.055706 | E10: 3.6192 | F10: 3.62 | G10: 0 | H10: real_gantt_duration_synchronized | I10: 80.484 | J10: 76.62 | K10: 3.864 | L10: 22
A11: 20260616_165213 | B11: 1 | C11: delay | D11: 16.384078 | E11: 1.797 | F11: 1.8 | G11: 0 | H11: real_gantt_duration_synchronized | I11: 73.41 | J11: 73.55 | K11: -0.14 | L11: 8
A12: 20260616_165213 | B12: 2 | C12: delay | D12: 18.20122 | E12: 3.594 | F12: 3.6 | G12: 0 | H12: real_gantt_duration_synchronized | I12: 77.01 | J12: 77.14 | K12: -0.13 | L12: 8
A13: 20260616_165213 | B13: 3 | C13: order | D13: 20.065596 | E13: 0 | F13: 3.86 | G13: 3.35 | H13: order_wrong_first_actual_plus_fixed_3.35_on_earlier_task | I13: 78.6938 | J13: 75.6 | K13: 3.0938 | L13: 8 | M13: 8 | N13: 6 | O13: 8 | P13: 6 | Q13: 7.32 | R13: 3.59 | S13: 7.32 | T13: 3.4638 | U13: 3.35 | V13: 5.4 | W13: 3.86
A14: 20260616_165213 | B14: 4 | C14: order | D14: 28.875026 | E14: 0 | F14: 0 | G14: 3.35 | H14: order_wrong_first_actual_plus_fixed_3.35_on_earlier_task | I14: 77.6238 | J14: 71.43 | K14: 6.1938 | L14: 10 | M14: 10 | N14: 12 | O14: 10 | P14: 12 | Q14: 2.22 | R14: 3.59 | S14: 2.22 | T14: 3.4638 | U14: 3.35 | V14: 1.24 | W14: 0
A15: 20260616_165213 | B15: 5 | C15: delay | D15: 41.343744 | E15: 1.79 | F15: 1.79 | G15: 0 | H15: real_gantt_duration_synchronized | I15: 77.9838 | J15: 72.49 | K15: 5.4938 | L15: 14
A16: 20260616_165213 | B16: 6 | C16: order | D16: 51.970007 | E16: 0 | F16: 0 | G16: 3.35 | H16: order_wrong_first_actual_plus_fixed_3.35_on_earlier_task | I16: 76.8138 | J16: 68.57 | K16: 8.2438 | L16: 18 | M16: 18 | N16: 19 | O16: 18 | P16: 19 | Q16: 3.04 | R16: 3.46 | S16: 3.04 | T16: 3.594 | U16: 3.35 | V16: 0.55 | W16: 0
A17: 20260616_165213 | B17: 7 | C17: delay | D17: 55.436669 | E17: 1.7319 | F17: 1.74 | G17: 0 | H17: real_gantt_duration_synchronized | I17: 75.6238 | J17: 70.3 | K17: 5.3238 | L17: 18
A18: 20260616_165213 | B18: 8 | C18: delay | D18: 62.271257 | E18: 2.9619 | F18: 2.97 | G18: 0 | H18: real_gantt_duration_synchronized | I18: 78.5938 | J18: 72.36 | K18: 6.2338 | L18: 21
A19: 20260616_165213 | B19: 9 | C19: delay | D19: 67.272864 | E19: 1.8096 | F19: 1.81 | G19: 0 | H19: real_gantt_duration_synchronized | I19: 78.7838 | J19: 72.64 | K19: 6.1438 | L19: 22
A20: 20260616_165213 | B20: 10 | C20: delay | D20: 72.496335 | E20: 1.797 | F20: 1.8 | G20: 0 | H20: real_gantt_duration_synchronized | I20: 80.2938 | J20: 74.21 | K20: 6.0838 | L20: 23
A21: 20260617_161127 | B21: 1 | C21: delay | D21: 17.060505 | E21: 1.797 | F21: 1.8 | G21: 0 | H21: real_gantt_duration_synchronized | I21: 74.19 | J21: 74.25 | K21: -0.06 | L21: 8
A22: 20260617_161127 | B22: 2 | C22: order | D22: 17.693304 | E22: 0 | F22: 0.78 | G22: 3.35 | H22: order_wrong_first_actual_plus_fixed_3.35_on_earlier_task | I22: 76.3938 | J22: 73.23 | K22: 3.1638 | L22: 8 | M22: 8 | N22: 6 | O22: 8 | P22: 6 | Q22: 4.24 | R22: 3.59 | S22: 4.24 | T22: 3.4638 | U22: 3.35 | V22: 1.8 | W22: 0.78
A23: 20260617_161127 | B23: 3 | C23: delay | D23: 29.531099 | E23: 1.7319 | F23: 1.74 | G23: 0 | H23: real_gantt_duration_synchronized | I23: 78.0238 | J23: 73.81 | K23: 4.2138 | L23: 12
A24: 20260617_161127 | B24: 4 | C24: delay | D24: 31.254966 | E24: 3.4638 | F24: 3.46 | G24: 0 | H24: real_gantt_duration_synchronized | I24: 81.4838 | J24: 77.27 | K24: 4.2138 | L24: 12
A25: 20260617_161127 | B25: 5 | C25: order | D25: 33.823369 | E25: 0 | F25: 4.18 | G25: 3.35 | H25: order_wrong_first_actual_plus_fixed_3.35_on_earlier_task | I25: 79.5076 | J25: 76.25 | K25: 3.2576 | L25: 10 | M25: 12 | N25: 10 | O25: 10 | P25: 12 | Q25: 3.46 | R25: 7.77 | S25: 3.46 | T25: 3.4638 | U25: 3.35 | V25: 5.2 | W25: 4.18
A26: 20260617_161127 | B26: 6 | C26: delay | D26: 47.69979 | E26: 1.79 | F26: 1.79 | G26: 0 | H26: real_gantt_duration_synchronized | I26: 80.9076 | J26: 75.56 | K26: 5.3476 | L26: 14
A27: 20260617_161127 | B27: 7 | C27: delay | D27: 56.865104 | E27: 1.7319 | F27: 1.74 | G27: 0 | H27: real_gantt_duration_synchronized | I27: 80.5876 | J27: 75.31 | K27: 5.2776 | L27: 18
A28: 20260617_161127 | B28: 8 | C28: delay | D28: 58.630231 | E28: 3.4638 | F28: 3.46 | G28: 0 | H28: real_gantt_duration_synchronized | I28: 84.0476 | J28: 78.78 | K28: 5.2676 | L28: 18
A29: 20260617_161127 | B29: 9 | C29: delay | D29: 63.184494 | E29: 1.797 | F29: 1.8 | G29: 0 | H29: real_gantt_duration_synchronized | I29: 83.3076 | J29: 78.07 | K29: 5.2376 | L29: 19
A30: 20260617_161127 | B30: 10 | C30: delay | D30: 64.967644 | E30: 3.594 | F30: 3.59 | G30: 0 | H30: real_gantt_duration_synchronized | I30: 86.8976 | J30: 81.66 | K30: 5.2376 | L30: 19
A31: 20260617_161127 | B31: 11 | C31: delay | D31: 68.592989 | E31: 7.188 | F31: 7.19 | G31: 0 | H31: real_gantt_duration_synchronized | I31: 94.0876 | J31: 88.85 | K31: 5.2376 | L31: 19
A32: 20260617_161127 | B32: 12 | C32: delay | D32: 75.274171 | E32: 2.9619 | F32: 2.97 | G32: 0 | H32: real_gantt_duration_synchronized | I32: 90.5876 | J32: 85.41 | K32: 5.1776 | L32: 21
A33: 20260617_161127 | B33: 13 | C33: delay | D33: 78.205221 | E33: 5.9238 | F33: 5.92 | G33: 0 | H33: real_gantt_duration_synchronized | I33: 96.5076 | J33: 91.33 | K33: 5.1776 | L33: 21
A34: 20260617_161127 | B34: 14 | C34: delay | D34: 84.158118 | E34: 11.8476 | F34: 11.85 | G34: 0 | H34: real_gantt_duration_synchronized | I34: 108.3576 | J34: 103.18 | K34: 5.1776 | L34: 21
A35: 20260617_161127 | B35: 15 | C35: delay | D35: 88.993244 | E35: 1.797 | F35: 1.8 | G35: 0 | H35: real_gantt_duration_synchronized | I35: 99.5176 | J35: 94.37 | K35: 5.1476 | L35: 23
A36: 20260617_161833 | B36: 1 | C36: order | D36: 16.974185 | E36: 0 | F36: 0 | G36: 3.35 | H36: order_wrong_first_actual_plus_fixed_3.35_on_earlier_task | I36: 75.41 | J36: 72.38 | K36: 3.03 | L36: 6 | M36: 6 | N36: 8 | O36: 6 | P36: 8 | Q36: 3.2 | R36: 3.46 | S36: 3.2 | T36: 3.594 | U36: 3.35 | V36: 0.39 | W36: 0
A37: 20260617_161833 | B37: 2 | C37: delay | D37: 27.657612 | E37: 1.797 | F37: 1.8 | G37: 0 | H37: real_gantt_duration_synchronized | I37: 76.26 | J37: 71.83 | K37: 4.43 | L37: 10
A38: 20260617_161833 | B38: 3 | C38: delay | D38: 29.432825 | E38: 3.594 | F38: 3.59 | G38: 0 | H38: real_gantt_duration_synchronized | I38: 79.85 | J38: 75.43 | K38: 4.42 | L38: 10
A39: 20260617_161833 | B39: 4 | C39: delay | D39: 33.042377 | E39: 7.188 | F39: 7.19 | G39: 0 | H39: real_gantt_duration_synchronized | I39: 87.0438 | J39: 80.28 | K39: 6.7638 | L39: 10
A40: 20260617_162610 | B40: 1 | C40: delay | D40: 17.853979 | E40: 1.797 | F40: 1.8 | G40: 0 | H40: real_gantt_duration_synchronized | I40: 74.92 | J40: 74.98 | K40: -0.06 | L40: 8
...

Sheet group_data
A1: caseID | B1: 失效次數 | C1: 失效任務個數 | D1: final_nores_makespan | E1: final_dynamic_makespan | F1: final_nores_minus_dynamic | G1: dynamic_final_better | H1: nores_final_better | I1: tie | J1: standardized_effect_rate | K1: effect_valid_5pct | L1: dynamic_effective_5pct | M1: human_nores_idle_ratio_higher | N1: robot_nores_idle_ratio_higher | O1: robot_nores_idle_ratio_higher_5pct | P1: failure_count_group | Q1: failure_count_group2 | R1: failed_task_count_group | S1: failed_task_count_group2 | T1: dynamic_better_effect_maksspan | U1: nores_better_effect_makespan
A2: 20260621_171234 | B2: 1 | C2: 1 | D2: =_xlfn.XLOOKUP(A2,batch_final_timeline_by_case!A:A,batch_final_timeline_by_case!D:D,"") -> 67.93 | E2: =_xlfn.XLOOKUP(A2,batch_final_timeline_by_case!A:A,batch_final_timeline_by_case!E:E,"") -> 65.52 | F2: =_xlfn.XLOOKUP(A2,batch_final_timeline_by_case!A:A,batch_final_timeline_by_case!F:F,"") -> 2.41 | G2: =_xlfn.XLOOKUP(A2,batch_final_timeline_by_case!A:A,batch_final_timeline_by_case!G:G,"") -> 1 | H2: =_xlfn.XLOOKUP(A2,batch_final_timeline_by_case!A:A,batch_final_timeline_by_case!H:H,"") -> 0 | I2: =_xlfn.XLOOKUP(A2,batch_final_timeline_by_case!A:A,batch_final_timeline_by_case!I:I,"") -> 0 | J2: =IF(D2=0,"",ABS(F2)/D2) -> 0.035477698 | K2: =IF(J2>=0.05,1,0) -> 0 | L2: =IF(AND(G2=1,K2=1),1,0) -> 0 | M2: =_xlfn.XLOOKUP(A2,idle_time_ratio_summary!A:A,idle_time_ratio_summary!G:G,"") -> 1 | N2: =_xlfn.XLOOKUP(A2,idle_time_ratio_summary!A:A,idle_time_ratio_summary!M:M,"") -> 1 | O2: =_xlfn.XLOOKUP(A2,idle_time_ratio_summary!A:A,idle_time_ratio_summary!N:N,"") -> 0 | P2: =IF(B2<=2,"1-2",IF(B2<=4,"3-4",IF(B2<=7,"5-7",IF(B2<=11,"8-11","12+")))) -> 1-2 | Q2: =IF(B2<=11,B2,IF(B2<20,"12-19","20+")) -> 1 | R2: =IF(C2<=3,"3-","4+") -> 3- | S2: =IF(C2<=7,C2,"8+") -> 1 | T2: =IF(G2=1,J2,0) -> 0.035477698 | U2: =IF(H2=1,ABS(F2)/E2,0) -> 0
A3: 20260621_222707 | B3: 1 | C3: 1 | D3: =_xlfn.XLOOKUP(A3,batch_final_timeline_by_case!A:A,batch_final_timeline_by_case!D:D,"") -> 68.34 | E3: =_xlfn.XLOOKUP(A3,batch_final_timeline_by_case!A:A,batch_final_timeline_by_case!E:E,"") -> 68.64 | F3: =_xlfn.XLOOKUP(A3,batch_final_timeline_by_case!A:A,batch_final_timeline_by_case!F:F,"") -> -0.3 | G3: =_xlfn.XLOOKUP(A3,batch_final_timeline_by_case!A:A,batch_final_timeline_by_case!G:G,"") -> 0 | H3: =_xlfn.XLOOKUP(A3,batch_final_timeline_by_case!A:A,batch_final_timeline_by_case!H:H,"") -> 1 | I3: =_xlfn.XLOOKUP(A3,batch_final_timeline_by_case!A:A,batch_final_timeline_by_case!I:I,"") -> 0 | J3: =IF(D3=0,"",ABS(F3)/D3) -> 0.0043898156 | K3: =IF(J3>=0.05,1,0) -> 0 | L3: =IF(AND(G3=1,K3=1),1,0) -> 0 | M3: =_xlfn.XLOOKUP(A3,idle_time_ratio_summary!A:A,idle_time_ratio_summary!G:G,"") -> 0 | N3: =_xlfn.XLOOKUP(A3,idle_time_ratio_summary!A:A,idle_time_ratio_summary!M:M,"") -> 0 | O3: =_xlfn.XLOOKUP(A3,idle_time_ratio_summary!A:A,idle_time_ratio_summary!N:N,"") -> 0 | P3: =IF(B3<=2,"1-2",IF(B3<=4,"3-4",IF(B3<=7,"5-7",IF(B3<=11,"8-11","12+")))) -> 1-2 | Q3: =IF(B3<=11,B3,IF(B3<20,"12-19","20+")) -> 1 | R3: =IF(C3<=3,"3-","4+") -> 3- | S3: =IF(C3<=7,C3,"8+") -> 1 | T3: =IF(G3=1,J3,0) -> 0 | U3: =IF(H3=1,ABS(F3)/E3,0) -> 0.0043706294
A4: 20260621_171649 | B4: 1 | C4: 1 | D4: =_xlfn.XLOOKUP(A4,batch_final_timeline_by_case!A:A,batch_final_timeline_by_case!D:D,"") -> 67.84 | E4: =_xlfn.XLOOKUP(A4,batch_final_timeline_by_case!A:A,batch_final_timeline_by_case!E:E,"") -> 65.87 | F4: =_xlfn.XLOOKUP(A4,batch_final_timeline_by_case!A:A,batch_final_timeline_by_case!F:F,"") -> 1.97 | G4: =_xlfn.XLOOKUP(A4,batch_final_timeline_by_case!A:A,batch_final_timeline_by_case!G:G,"") -> 1 | H4: =_xlfn.XLOOKUP(A4,batch_final_timeline_by_case!A:A,batch_final_timeline_by_case!H:H,"") -> 0 | I4: =_xlfn.XLOOKUP(A4,batch_final_timeline_by_case!A:A,batch_final_timeline_by_case!I:I,"") -> 0 | J4: =IF(D4=0,"",ABS(F4)/D4) -> 0.029038915 | K4: =IF(J4>=0.05,1,0) -> 0 | L4: =IF(AND(G4=1,K4=1),1,0) -> 0 | M4: =_xlfn.XLOOKUP(A4,idle_time_ratio_summary!A:A,idle_time_ratio_summary!G:G,"") -> 1 | N4: =_xlfn.XLOOKUP(A4,idle_time_ratio_summary!A:A,idle_time_ratio_summary!M:M,"") -> 1 | O4: =_xlfn.XLOOKUP(A4,idle_time_ratio_summary!A:A,idle_time_ratio_summary!N:N,"") -> 0 | P4: =IF(B4<=2,"1-2",IF(B4<=4,"3-4",IF(B4<=7,"5-7",IF(B4<=11,"8-11","12+")))) -> 1-2 | Q4: =IF(B4<=11,B4,IF(B4<20,"12-19","20+")) -> 1 | R4: =IF(C4<=3,"3-","4+") -> 3- | S4: =IF(C4<=7,C4,"8+") -> 1 | T4: =IF(G4=1,J4,0) -> 0.029038915 | U4: =IF(H4=1,ABS(F4)/E4,0) -> 0
A5: 20260618_150754 | B5: 2 | C5: 1 | D5: =_xlfn.XLOOKUP(A5,batch_final_timeline_by_case!A:A,batch_final_timeline_by_case!D:D,"") -> 68.39 | E5: =_xlfn.XLOOKUP(A5,batch_final_timeline_by_case!A:A,batch_final_timeline_by_case!E:E,"") -> 68.43 | F5: =_xlfn.XLOOKUP(A5,batch_final_timeline_by_case!A:A,batch_final_timeline_by_case!F:F,"") -> -0.04 | G5: =_xlfn.XLOOKUP(A5,batch_final_timeline_by_case!A:A,batch_final_timeline_by_case!G:G,"") -> 0 | H5: =_xlfn.XLOOKUP(A5,batch_final_timeline_by_case!A:A,batch_final_timeline_by_case!H:H,"") -> 1 | I5: =_xlfn.XLOOKUP(A5,batch_final_timeline_by_case!A:A,batch_final_timeline_by_case!I:I,"") -> 0 | J5: =IF(D5=0,"",ABS(F5)/D5) -> 0.00058488083 | K5: =IF(J5>=0.05,1,0) -> 0 | L5: =IF(AND(G5=1,K5=1),1,0) -> 0 | M5: =_xlfn.XLOOKUP(A5,idle_time_ratio_summary!A:A,idle_time_ratio_summary!G:G,"") -> 0 | N5: =_xlfn.XLOOKUP(A5,idle_time_ratio_summary!A:A,idle_time_ratio_summary!M:M,"") -> 0 | O5: =_xlfn.XLOOKUP(A5,idle_time_ratio_summary!A:A,idle_time_ratio_summary!N:N,"") -> 0 | P5: =IF(B5<=2,"1-2",IF(B5<=4,"3-4",IF(B5<=7,"5-7",IF(B5<=11,"8-11","12+")))) -> 1-2 | Q5: =IF(B5<=11,B5,IF(B5<20,"12-19","20+")) -> 2 | R5: =IF(C5<=3,"3-","4+") -> 3- | S5: =IF(C5<=7,C5,"8+") -> 1 | T5: =IF(G5=1,J5,0) -> 0 | U5: =IF(H5=1,ABS(F5)/E5,0) -> 0.00058453894
A6: 20260621_172604 | B6: 1 | C6: 1 | D6: =_xlfn.XLOOKUP(A6,batch_final_timeline_by_case!A:A,batch_final_timeline_by_case!D:D,"") -> 67.71 | E6: =_xlfn.XLOOKUP(A6,batch_final_timeline_by_case!A:A,batch_final_timeline_by_case!E:E,"") -> 63.7 | F6: =_xlfn.XLOOKUP(A6,batch_final_timeline_by_case!A:A,batch_final_timeline_by_case!F:F,"") -> 4.01 | G6: =_xlfn.XLOOKUP(A6,batch_final_timeline_by_case!A:A,batch_final_timeline_by_case!G:G,"") -> 1 | H6: =_xlfn.XLOOKUP(A6,batch_final_timeline_by_case!A:A,batch_final_timeline_by_case!H:H,"") -> 0 | I6: =_xlfn.XLOOKUP(A6,batch_final_timeline_by_case!A:A,batch_final_timeline_by_case!I:I,"") -> 0 | J6: =IF(D6=0,"",ABS(F6)/D6) -> 0.059223158 | K6: =IF(J6>=0.05,1,0) -> 1 | L6: =IF(AND(G6=1,K6=1),1,0) -> 1 | M6: =_xlfn.XLOOKUP(A6,idle_time_ratio_summary!A:A,idle_time_ratio_summary!G:G,"") -> 1 | N6: =_xlfn.XLOOKUP(A6,idle_time_ratio_summary!A:A,idle_time_ratio_summary!M:M,"") -> 1 | O6: =_xlfn.XLOOKUP(A6,idle_time_ratio_summary!A:A,idle_time_ratio_summary!N:N,"") -> 1 | P6: =IF(B6<=2,"1-2",IF(B6<=4,"3-4",IF(B6<=7,"5-7",IF(B6<=11,"8-11","12+")))) -> 1-2 | Q6: =IF(B6<=11,B6,IF(B6<20,"12-19","20+")) -> 1 | R6: =IF(C6<=3,"3-","4+") -> 3- | S6: =IF(C6<=7,C6,"8+") -> 1 | T6: =IF(G6=1,J6,0) -> 0.059223158 | U6: =IF(H6=1,ABS(F6)/E6,0) -> 0
A7: 20260618_180614 | B7: 4 | C7: 1 | D7: =_xlfn.XLOOKUP(A7,batch_final_timeline_by_case!A:A,batch_final_timeline_by_case!D:D,"") -> 85.1592 | E7: =_xlfn.XLOOKUP(A7,batch_final_timeline_by_case!A:A,batch_final_timeline_by_case!E:E,"") -> 81.6 | F7: =_xlfn.XLOOKUP(A7,batch_final_timeline_by_case!A:A,batch_final_timeline_by_case!F:F,"") -> 3.5592 | G7: =_xlfn.XLOOKUP(A7,batch_final_timeline_by_case!A:A,batch_final_timeline_by_case!G:G,"") -> 1 | H7: =_xlfn.XLOOKUP(A7,batch_final_timeline_by_case!A:A,batch_final_timeline_by_case!H:H,"") -> 0 | I7: =_xlfn.XLOOKUP(A7,batch_final_timeline_by_case!A:A,batch_final_timeline_by_case!I:I,"") -> 0 | J7: =IF(D7=0,"",ABS(F7)/D7) -> 0.041794662 | K7: =IF(J7>=0.05,1,0) -> 0 | L7: =IF(AND(G7=1,K7=1),1,0) -> 0 | M7: =_xlfn.XLOOKUP(A7,idle_time_ratio_summary!A:A,idle_time_ratio_summary!G:G,"") -> 0 | N7: =_xlfn.XLOOKUP(A7,idle_time_ratio_summary!A:A,idle_time_ratio_summary!M:M,"") -> 1 | O7: =_xlfn.XLOOKUP(A7,idle_time_ratio_summary!A:A,idle_time_ratio_summary!N:N,"") -> 1 | P7: =IF(B7<=2,"1-2",IF(B7<=4,"3-4",IF(B7<=7,"5-7",IF(B7<=11,"8-11","12+")))) -> 3-4 | Q7: =IF(B7<=11,B7,IF(B7<20,"12-19","20+")) -> 4 | R7: =IF(C7<=3,"3-","4+") -> 3- | S7: =IF(C7<=7,C7,"8+") -> 1 | T7: =IF(G7=1,J7,0) -> 0.041794662 | U7: =IF(H7=1,ABS(F7)/E7,0) -> 0
A8: 20260621_174256 | B8: 2 | C8: 1 | D8: =_xlfn.XLOOKUP(A8,batch_final_timeline_by_case!A:A,batch_final_timeline_by_case!D:D,"") -> 72.9992 | E8: =_xlfn.XLOOKUP(A8,batch_final_timeline_by_case!A:A,batch_final_timeline_by_case!E:E,"") -> 69.32 | F8: =_xlfn.XLOOKUP(A8,batch_final_timeline_by_case!A:A,batch_final_timeline_by_case!F:F,"") -> 3.6792 | G8: =_xlfn.XLOOKUP(A8,batch_final_timeline_by_case!A:A,batch_final_timeline_by_case!G:G,"") -> 1 | H8: =_xlfn.XLOOKUP(A8,batch_final_timeline_by_case!A:A,batch_final_timeline_by_case!H:H,"") -> 0 | I8: =_xlfn.XLOOKUP(A8,batch_final_timeline_by_case!A:A,batch_final_timeline_by_case!I:I,"") -> 0 | J8: =IF(D8=0,"",ABS(F8)/D8) -> 0.050400552 | K8: =IF(J8>=0.05,1,0) -> 1 | L8: =IF(AND(G8=1,K8=1),1,0) -> 1 | M8: =_xlfn.XLOOKUP(A8,idle_time_ratio_summary!A:A,idle_time_ratio_summary!G:G,"") -> 0 | N8: =_xlfn.XLOOKUP(A8,idle_time_ratio_summary!A:A,idle_time_ratio_summary!M:M,"") -> 1 | O8: =_xlfn.XLOOKUP(A8,idle_time_ratio_summary!A:A,idle_time_ratio_summary!N:N,"") -> 0 | P8: =IF(B8<=2,"1-2",IF(B8<=4,"3-4",IF(B8<=7,"5-7",IF(B8<=11,"8-11","12+")))) -> 1-2 | Q8: =IF(B8<=11,B8,IF(B8<20,"12-19","20+")) -> 2 | R8: =IF(C8<=3,"3-","4+") -> 3- | S8: =IF(C8<=7,C8,"8+") -> 1 | T8: =IF(G8=1,J8,0) -> 0.050400552 | U8: =IF(H8=1,ABS(F8)/E8,0) -> 0
A9: 20260617_225645 | B9: 4 | C9: 1 | D9: =_xlfn.XLOOKUP(A9,batch_final_timeline_by_case!A:A,batch_final_timeline_by_case!D:D,"") -> 75.8538 | E9: =_xlfn.XLOOKUP(A9,batch_final_timeline_by_case!A:A,batch_final_timeline_by_case!E:E,"") -> 81.77 | F9: =_xlfn.XLOOKUP(A9,batch_final_timeline_by_case!A:A,batch_final_timeline_by_case!F:F,"") -> -5.9162 | G9: =_xlfn.XLOOKUP(A9,batch_final_timeline_by_case!A:A,batch_final_timeline_by_case!G:G,"") -> 0 | H9: =_xlfn.XLOOKUP(A9,batch_final_timeline_by_case!A:A,batch_final_timeline_by_case!H:H,"") -> 1 | I9: =_xlfn.XLOOKUP(A9,batch_final_timeline_by_case!A:A,batch_final_timeline_by_case!I:I,"") -> 0 | J9: =IF(D9=0,"",ABS(F9)/D9) -> 0.077994774 | K9: =IF(J9>=0.05,1,0) -> 1 | L9: =IF(AND(G9=1,K9=1),1,0) -> 0 | M9: =_xlfn.XLOOKUP(A9,idle_time_ratio_summary!A:A,idle_time_ratio_summary!G:G,"") -> 0 | N9: =_xlfn.XLOOKUP(A9,idle_time_ratio_summary!A:A,idle_time_ratio_summary!M:M,"") -> 1 | O9: =_xlfn.XLOOKUP(A9,idle_time_ratio_summary!A:A,idle_time_ratio_summary!N:N,"") -> 1 | P9: =IF(B9<=2,"1-2",IF(B9<=4,"3-4",IF(B9<=7,"5-7",IF(B9<=11,"8-11","12+")))) -> 3-4 | Q9: =IF(B9<=11,B9,IF(B9<20,"12-19","20+")) -> 4 | R9: =IF(C9<=3,"3-","4+") -> 3- | S9: =IF(C9<=7,C9,"8+") -> 1 | T9: =IF(G9=1,J9,0) -> 0 | U9: =IF(H9=1,ABS(F9)/E9,0) -> 0.072351718
A10: 20260621_184824 | B10: 2 | C10: 1 | D10: =_xlfn.XLOOKUP(A10,batch_final_timeline_by_case!A:A,batch_final_timeline_by_case!D:D,"") -> 68.07 | E10: =_xlfn.XLOOKUP(A10,batch_final_timeline_by_case!A:A,batch_final_timeline_by_case!E:E,"") -> 63.33 | F10: =_xlfn.XLOOKUP(A10,batch_final_timeline_by_case!A:A,batch_final_timeline_by_case!F:F,"") -> 4.74 | G10: =_xlfn.XLOOKUP(A10,batch_final_timeline_by_case!A:A,batch_final_timeline_by_case!G:G,"") -> 1 | H10: =_xlfn.XLOOKUP(A10,batch_final_timeline_by_case!A:A,batch_final_timeline_by_case!H:H,"") -> 0 | I10: =_xlfn.XLOOKUP(A10,batch_final_timeline_by_case!A:A,batch_final_timeline_by_case!I:I,"") -> 0 | J10: =IF(D10=0,"",ABS(F10)/D10) -> 0.0696342 | K10: =IF(J10>=0.05,1,0) -> 1 | L10: =IF(AND(G10=1,K10=1),1,0) -> 1 | M10: =_xlfn.XLOOKUP(A10,idle_time_ratio_summary!A:A,idle_time_ratio_summary!G:G,"") -> 0 | N10: =_xlfn.XLOOKUP(A10,idle_time_ratio_summary!A:A,idle_time_ratio_summary!M:M,"") -> 1 | O10: =_xlfn.XLOOKUP(A10,idle_time_ratio_summary!A:A,idle_time_ratio_summary!N:N,"") -> 1 | P10: =IF(B10<=2,"1-2",IF(B10<=4,"3-4",IF(B10<=7,"5-7",IF(B10<=11,"8-11","12+")))) -> 1-2 | Q10: =IF(B10<=11,B10,IF(B10<20,"12-19","20+")) -> 2 | R10: =IF(C10<=3,"3-","4+") -> 3- | S10: =IF(C10<=7,C10,"8+") -> 1 | T10: =IF(G10=1,J10,0) -> 0.0696342 | U10: =IF(H10=1,ABS(F10)/E10,0) -> 0
A11: 20260621_170757 | B11: 1 | C11: 1 | D11: =_xlfn.XLOOKUP(A11,batch_final_timeline_by_case!A:A,batch_final_timeline_by_case!D:D,"") -> 67.85 | E11: =_xlfn.XLOOKUP(A11,batch_final_timeline_by_case!A:A,batch_final_timeline_by_case!E:E,"") -> 65.35 | F11: =_xlfn.XLOOKUP(A11,batch_final_timeline_by_case!A:A,batch_final_timeline_by_case!F:F,"") -> 2.5 | G11: =_xlfn.XLOOKUP(A11,batch_final_timeline_by_case!A:A,batch_final_timeline_by_case!G:G,"") -> 1 | H11: =_xlfn.XLOOKUP(A11,batch_final_timeline_by_case!A:A,batch_final_timeline_by_case!H:H,"") -> 0 | I11: =_xlfn.XLOOKUP(A11,batch_final_timeline_by_case!A:A,batch_final_timeline_by_case!I:I,"") -> 0 | J11: =IF(D11=0,"",ABS(F11)/D11) -> 0.036845984 | K11: =IF(J11>=0.05,1,0) -> 0 | L11: =IF(AND(G11=1,K11=1),1,0) -> 0 | M11: =_xlfn.XLOOKUP(A11,idle_time_ratio_summary!A:A,idle_time_ratio_summary!G:G,"") -> 1 | N11: =_xlfn.XLOOKUP(A11,idle_time_ratio_summary!A:A,idle_time_ratio_summary!M:M,"") -> 1 | O11: =_xlfn.XLOOKUP(A11,idle_time_ratio_summary!A:A,idle_time_ratio_summary!N:N,"") -> 0 | P11: =IF(B11<=2,"1-2",IF(B11<=4,"3-4",IF(B11<=7,"5-7",IF(B11<=11,"8-11","12+")))) -> 1-2 | Q11: =IF(B11<=11,B11,IF(B11<20,"12-19","20+")) -> 1 | R11: =IF(C11<=3,"3-","4+") -> 3- | S11: =IF(C11<=7,C11,"8+") -> 1 | T11: =IF(G11=1,J11,0) -> 0.036845984 | U11: =IF(H11=1,ABS(F11)/E11,0) -> 0
A12: 20260621_185411 | B12: 1 | C12: 1 | D12: =_xlfn.XLOOKUP(A12,batch_final_timeline_by_case!A:A,batch_final_timeline_by_case!D:D,"") -> 68.34 | E12: =_xlfn.XLOOKUP(A12,batch_final_timeline_by_case!A:A,batch_final_timeline_by_case!E:E,"") -> 67.65 | F12: =_xlfn.XLOOKUP(A12,batch_final_timeline_by_case!A:A,batch_final_timeline_by_case!F:F,"") -> 0.69 | G12: =_xlfn.XLOOKUP(A12,batch_final_timeline_by_case!A:A,batch_final_timeline_by_case!G:G,"") -> 1 | H12: =_xlfn.XLOOKUP(A12,batch_final_timeline_by_case!A:A,batch_final_timeline_by_case!H:H,"") -> 0 | I12: =_xlfn.XLOOKUP(A12,batch_final_timeline_by_case!A:A,batch_final_timeline_by_case!I:I,"") -> 0 | J12: =IF(D12=0,"",ABS(F12)/D12) -> 0.010096576 | K12: =IF(J12>=0.05,1,0) -> 0 | L12: =IF(AND(G12=1,K12=1),1,0) -> 0 | M12: =_xlfn.XLOOKUP(A12,idle_time_ratio_summary!A:A,idle_time_ratio_summary!G:G,"") -> 0 | N12: =_xlfn.XLOOKUP(A12,idle_time_ratio_summary!A:A,idle_time_ratio_summary!M:M,"") -> 1 | O12: =_xlfn.XLOOKUP(A12,idle_time_ratio_summary!A:A,idle_time_ratio_summary!N:N,"") -> 0 | P12: =IF(B12<=2,"1-2",IF(B12<=4,"3-4",IF(B12<=7,"5-7",IF(B12<=11,"8-11","12+")))) -> 1-2 | Q12: =IF(B12<=11,B12,IF(B12<20,"12-19","20+")) -> 1 | R12: =IF(C12<=3,"3-","4+") -> 3- | S12: =IF(C12<=7,C12,"8+") -> 1 | T12: =IF(G12=1,J12,0) -> 0.010096576 | U12: =IF(H12=1,ABS(F12)/E12,0) -> 0
A13: 20260618_175053 | B13: 2 | C13: 1 | D13: =_xlfn.XLOOKUP(A13,batch_final_timeline_by_case!A:A,batch_final_timeline_by_case!D:D,"") -> 67.81 | E13: =_xlfn.XLOOKUP(A13,batch_final_timeline_by_case!A:A,batch_final_timeline_by_case!E:E,"") -> 68.72 | F13: =_xlfn.XLOOKUP(A13,batch_final_timeline_by_case!A:A,batch_final_timeline_by_case!F:F,"") -> -0.91 | G13: =_xlfn.XLOOKUP(A13,batch_final_timeline_by_case!A:A,batch_final_timeline_by_case!G:G,"") -> 0 | H13: =_xlfn.XLOOKUP(A13,batch_final_timeline_by_case!A:A,batch_final_timeline_by_case!H:H,"") -> 1 | I13: =_xlfn.XLOOKUP(A13,batch_final_timeline_by_case!A:A,batch_final_timeline_by_case!I:I,"") -> 0 | J13: =IF(D13=0,"",ABS(F13)/D13) -> 0.01341985 | K13: =IF(J13>=0.05,1,0) -> 0 | L13: =IF(AND(G13=1,K13=1),1,0) -> 0 | M13: =_xlfn.XLOOKUP(A13,idle_time_ratio_summary!A:A,idle_time_ratio_summary!G:G,"") -> 0 | N13: =_xlfn.XLOOKUP(A13,idle_time_ratio_summary!A:A,idle_time_ratio_summary!M:M,"") -> 0 | O13: =_xlfn.XLOOKUP(A13,idle_time_ratio_summary!A:A,idle_time_ratio_summary!N:N,"") -> 0 | P13: =IF(B13<=2,"1-2",IF(B13<=4,"3-4",IF(B13<=7,"5-7",IF(B13<=11,"8-11","12+")))) -> 1-2 | Q13: =IF(B13<=11,B13,IF(B13<20,"12-19","20+")) -> 2 | R13: =IF(C13<=3,"3-","4+") -> 3- | S13: =IF(C13<=7,C13,"8+") -> 1 | T13: =IF(G13=1,J13,0) -> 0 | U13: =IF(H13=1,ABS(F13)/E13,0) -> 0.013242142
... A72: 20260617_220342 | B72: 27 | C72: 11 | D72: =_xlfn.XLOOKUP(A72,batch_final_timeline_by_case!A:A,batch_final_timeline_by_case!D:D,"") -> 169.9192 | E72: =_xlfn.XLOOKUP(A72,batch_final_timeline_by_case!A:A,batch_final_timeline_by_case!E:E,"") -> 166.98 | F72: =_xlfn.XLOOKUP(A72,batch_final_timeline_by_case!A:A,batch_final_timeline_by_case!F:F,"") -> 2.9392 | G72: =_xlfn.XLOOKUP(A72,batch_final_timeline_by_case!A:A,batch_final_timeline_by_case!G:G,"") -> 1 | H72: =_xlfn.XLOOKUP(A72,batch_final_timeline_by_case!A:A,batch_final_timeline_by_case!H:H,"") -> 0 | I72: =_xlfn.XLOOKUP(A72,batch_final_timeline_by_case!A:A,batch_final_timeline_by_case!I:I,"") -> 0 | J72: =IF(D72=0,"",ABS(F72)/D72) -> 0.017297633 | K72: =IF(J72>=0.05,1,0) -> 0 | L72: =IF(AND(G72=1,K72=1),1,0) -> 0 | M72: =_xlfn.XLOOKUP(A72,idle_time_ratio_summary!A:A,idle_time_ratio_summary!G:G,"") -> 0 | N72: =_xlfn.XLOOKUP(A72,idle_time_ratio_summary!A:A,idle_time_ratio_summary!M:M,"") -> 1 | O72: =_xlfn.XLOOKUP(A72,idle_time_ratio_summary!A:A,idle_time_ratio_summary!N:N,"") -> 1 | P72: =IF(B72<=2,"1-2",IF(B72<=4,"3-4",IF(B72<=7,"5-7",IF(B72<=11,"8-11","12+")))) -> 12+ | Q72: =IF(B72<=11,B72,IF(B72<20,"12-19","20+")) -> 20+ | R72: =IF(C72<=3,"3-","4+") -> 4+ | S72: =IF(C72<=7,C72,"8+") -> 8+ | T72: =IF(G72=1,J72,0) -> 0.017297633 | U72: =IF(H72=1,ABS(F72)/E72,0) -> 0
G73: =SUM(G2:G72) -> 46 | H73: =SUM(H2:H72) -> 25 | J73: =AVERAGE(J2:J72) -> 0.03449459 | K73: =SUM(K2:K72) -> 16 | L73: =SUM(L2:L72) -> 14 | M73: =SUM(M2:M72) -> 11 | N73: =SUM(N2:N72) -> 54 | O73: =SUM(O2:O72) -> 38 | T73: =AVERAGE(T2:T72) -> 0.025252708 | U73: =AVERAGE(U2:U72) -> 0.0088655552

Sheet 失效次數分析
A3: 列標籤 | B3: caseID | C3: Dynamic makespan較佳比例 | D3: Nores human等待時間較佳比例 | E3: Dynamic robot等待時間較佳比例 | F3: Dynamic robot等待時間較佳比例(>=5%) | G3: 平均值 - dynamic_effective_5pct
A4: 1-2 | B4: 14 | C4: 0.71428571 | D4: 0.42857143 | E4: 0.64285714 | F4: 0.14285714 | G4: 0.21428571
A5: 3-4 | B5: 15 | C5: 0.73333333 | D5: 0.26666667 | E5: 0.8 | F5: 0.4 | G5: 0.13333333
A6: 5-7 | B6: 17 | C6: 0.52941176 | D6: 0.058823529 | E6: 0.76470588 | F6: 0.70588235 | G6: 0.17647059
A7: 8-11 | B7: 16 | C7: 0.5625 | D7: 0 | E7: 0.75 | F7: 0.6875 | G7: 0.25
A8: 12+ | B8: 9 | C8: 0.77777778 | D8: 0 | E8: 0.88888889 | F8: 0.77777778 | G8: 0.22222222

Sheet 失效任務個數分析
A3: 列標籤 | B3: 計數 - caseID | C3: Dynamic makespna較佳比例 | D3: Dynamic 等待時間較佳比例 | E3: Dynamic 等待時間較佳比例(>=5%) | F3: 平均值 - dynamic_effective_5pct
A4: 3- | B4: 37 | C4: 0.72972973 | D4: 0.81081081 | E4: 0.45945946 | F4: 0.16216216
A5: 1 | B5: 13 | C5: 0.69230769 | D5: 0.76923077 | E5: 0.30769231 | F5: 0.23076923
A6: 2 | B6: 16 | C6: 0.75 | D6: 0.75 | E6: 0.5625 | F6: 0.0625
A7: 3 | B7: 8 | C7: 0.75 | D7: 1 | E7: 0.5 | F7: 0.25
A8: 4+ | B8: 34 | C8: 0.55882353 | D8: 0.70588235 | E8: 0.61764706 | F8: 0.23529412
